Workbook

Sheet 00 - Controle V1.0
A1: MÉTODO JABES — V1.0 FINAL
A3: Status | B3: VERSÃO CONGELADA PARA TESTE REAL
A4: Objetivo | B4: Padrão de análise individual de cada imóvel.
A5: Hard Stops | B5: Evicção não comprovada, risco jurídico relevante, documentação inconsistente ou custo/lance fora do limite.
A6: Pré-lance | B6: Revalidação obrigatória antes de qualquer lance.
A7: Rastreabilidade | B7: Fonte, link/documento e data da consulta nos pontos críticos.
A8: Leiloeiro | B8: Dados, conferência cruzada e histórico.
A9: Veredito | B9: A / B / C / D / E.
A10: Regra de evolução | B10: Após 10–20 análises reais, revisar critérios somente se houver evidência de necessidade.

Sheet 01 - Veredito
A1: MÉTODO JABES V2 — VEREDITO
A2: 🔵 INPUT manual | 🟢 cálculo | Registre evidências e fontes
A4: 🎯 IDENTIFICAÇÃO
A5: Campo | B5: Valor | C5: Observação | D5: Fonte | E5: Data
A6: ID imóvel
A7: Nome / identificação
A8: Endereço
A9: Cidade / UF
A10: Matrícula
A11: Data da análise
A12: Origem / leilão
A13: Status
A16: ⭐ PAINEL EXECUTIVO
A17: Indicador | B17: Resultado | C17: Critério | D17: Fonte
A18: Segurança jurídica | B18: ='02 - Due Diligence'!B78 -> 100
A19: Localização | B19: ='05 - Mercado'!B32 -> 85
A20: Liquidez | B20: ='05 - Mercado'!B33 -> 80
A21: Financeiro / ROI | B21: ='04 - Financeiro'!B34*100 -> 20.100739
A22: Contexto humano | B22: ='06 - Contexto Humano'!B20 -> 85
A23: Score final | B23: =AVERAGE(B18:B22) -> 74.020148
A25: Preço máximo recomendado | B25: ='04 - Financeiro'!B73 -> 168374.76
A26: Lance / preço atual | B26: ='04 - Financeiro'!B6 -> 191651.31
A27: ROI líquido estimado | B27: ='04 - Financeiro'!B34 -> 0.20100739
A28: Yield líquido anual | B28: ='04 - Financeiro'!B52 -> 0.061560884
A29: DECISÃO FINAL | C29: COMPRAR / ACOMPANHAR / NÃO ENTRAR / REPROVAR
A32: VEREDITO PADRÃO MÉTODO JABES V1.0
A33: A | B33: ARREMATAR | C33: Excelente relação risco × retorno
A34: B | B34: ARREMATAR ATÉ R$ X | C34: Bom negócio, com teto definido
A35: C | B35: MONITORAR | C35: Interessante, mas diligência incompleta
A36: D | B36: SÓ SE CAIR PARA R$ X | C36: Imóvel bom, preço atual não compensa
A37: E | B37: REPROVAR | C37: Não participar
A39: REGRA CENTRAL
A40: Imóvel bom ≠ bom arremate. O lance máximo é definido pelo risco, mercado e custo total — nunca pela disputa.

Sheet 02 - Due Diligence
A1: 02 — DUE DILIGENCE — 71 CRITÉRIOS
A2: 🔵 INPUT manual | 🟢 cálculo | Registre evidências e fontes
A4: ⚖️ CHECKLIST MESTRE
A5: ID | B5: Bloco | C5: Critério | D5: Resultado | E5: Valor/Nota | F5: Evidência / Fonte | G5: Data da consulta | H5: Link / Documento | I5: Observações
A6: 1 | B6: Matrícula identificada | D6: OK
A7: 2 | B7: Matrícula atualizada | D7: OK
A8: 3 | B8: Cadeia dominial | D8: OK
A9: 4 | B9: Venda fiduciária | D9: OK
A10: 5 | B10: Consolidação | D10: OK
A11: 6 | B11: Constituição em mora | D11: OK
A12: 7 | B12: Purga da mora | D12: OK
A13: 8 | B13: Intimação | D13: OK
A14: 9 | B14: Penhora | D14: OK
A15: 10 | B15: Indisponibilidade / arresto | D15: OK
A16: 11 | B16: Hipoteca / outros ônus | D16: OK
A17: 12 | B17: Usufruto / direitos de terceiros | D17: OK
... A76: 71 | B76: Status | D76: OK
B78: =IF(COUNTIF(D6:D76,"REPROVAR")>0,0,IF(COUNTIF(D6:D76,"ATENÇÃO")>0,60,100)) -> 100
A80: EVICÇÃO DE DIREITO — HARD STOP
A81: E01 | B81: Jurídico | C81: Existe cláusula expressa de garantia contra evicção no edital? | D81: OK
A82: E02 | B82: Jurídico | C82: Qual item/página do edital contém a garantia? | D82: OK | E82: Item 18.1
A83: E03 | B83: Jurídico | C83: A redação cobre perda do imóvel por direito de terceiro? | D83: OK
A84: E04 | B84: Jurídico | C84: Existem exclusões, ressalvas ou limitações relevantes? | D84: OK
A85: E05 | B85: Jurídico | C85: Existem ações reais/reipersecutórias ou direitos de terceiros? | D85: OK
A86: E06 | B86: Jurídico | C86: A cadeia dominial apresenta algum risco residual? | D86: OK
A87: E07 | B87: Jurídico | C87: A garantia é compatível com esta modalidade de venda? | D87: OK
A88: E08 | B88: Jurídico | C88: Trecho do edital comprobatório registrado? | D88: OK | F88: Edital vigente | G88: 14/09/2026
A89: E09 | B89: Jurídico | C89: Conclusão de evicção: OK / ATENÇÃO / REPROVAR? | D89: OK
A91: REGRA HARD STOP
A92: Sem confirmação documental da garantia de evicção = NÃO LIBERAR LANCE.

Sheet 03 - Processos Jurídicos
A1: 03 — PROCESSOS JURÍDICOS
A2: 🔵 INPUT manual | 🟢 cálculo | Registre evidências e fontes
A4: ID imóvel | B4: Nº processo | C4: Tribunal / comarca | D4: Parte / proprietário | E4: Polo | F4: Assunto | G4: Situação | H4: Última movimentação | I4: Risco | J4: Impacto | K4: Fonte/link | L4: Observações

Sheet 04 - Financeiro
A1: 04 — FINANCEIRO
A2: 🔵 INPUT manual | 🟢 cálculo | Registre evidências e fontes
A4: 💰 AQUISIÇÃO
A5: Campo | B5: Valor | C5: Tipo | D5: Observação | E5: Fonte
A6: Lance / preço de compra | B6: 191651.31 | C6: INPUT
A7: Comissão leiloeiro (%) | B7: 0.05 | C7: INPUT
A8: Comissão leiloeiro (R$) | B8: =B6*B7 -> 9582.5655 | C8: CALCULADO
A9: ITBI (%) | B9: 0.02 | C9: INPUT
A10: ITBI (R$) | B10: =B6*B9 -> 3833.0262 | C10: CALCULADO
A11: Registro / documentação | B11: 3000 | C11: INPUT
A12: Condomínio / débitos | B12: 5000 | C12: INPUT
A13: Tributos / débitos | B13: 0 | C13: INPUT
A14: Reforma | B14: 10000 | C14: INPUT
A15: Reserva / imprevistos | B15: 5000 | C15: INPUT
A16: Custo jurídico preventivo | B16: 0 | C16: INPUT
A17: Custo potencial jurídico | B17: 0 | C17: INPUT
A18: Probabilidade jurídica (%) | B18: 0 | C18: INPUT
A19: Custo jurídico esperado | B19: =B17*B18 -> 0 | C19: CALCULADO
A20: Reserva risco jurídico | B20: =B19 -> 0 | C20: CALCULADO
A21: CUSTO TOTAL AQUISIÇÃO | B21: =SUM(B6,B8,B10:B17,B20) -> 228066.9 | C21: CALCULADO
A23: 🏷️ VENDA
A24: Campo | B24: Valor | C24: Tipo | D24: Observação | E24: Fonte
A25: Preço de venda | B25: 300000 | C25: INPUT
A26: Corretagem venda (%) | B26: 0.06 | C26: INPUT
A27: Corretagem venda (R$) | B27: =B25*B26 -> 18000 | C27: CALCULADO
A28: Outros custos venda | B28: 0 | C28: INPUT
A29: Base IR | B29: =MAX(0,B25-B27-B28-B21) -> 53933.098 | C29: CALCULADO
A30: IR (%) | B30: 0.15 | C30: INPUT
A31: IR estimado | B31: =B29*B30 -> 8089.9647 | C31: CALCULADO
A32: VENDA LÍQUIDA | B32: =B25-B27-B28-B31 -> 273910.04 | C32: CALCULADO
A33: LUCRO LÍQUIDO | B33: =B32-B21 -> 45843.134 | C33: CALCULADO
A34: ROI LÍQUIDO | B34: =IFERROR(B33/B21,0) -> 0.20100739 | C34: CALCULADO
A35: MARGEM LÍQUIDA | B35: =IFERROR(B33/B25,0) -> 0.15281045 | C35: CALCULADO
A38: 🏠 ALUGUEL
A39: Campo | B39: Valor | C39: Tipo | D39: Observação | E39: Fonte
A40: Aluguel mensal bruto | B40: 1900 | C40: INPUT
A41: Condomínio mensal | B41: 510 | C41: INPUT
A42: IPTU mensal | B42: 25 | C42: INPUT
A43: Seguro/taxas | B43: 0 | C43: INPUT
A44: Manutenção | B44: 100 | C44: INPUT
...

Sheet 05 - Mercado
A1: 05 — MERCADO
A2: 🔵 INPUT manual | 🟢 cálculo | Registre evidências e fontes
A4: 🏘️ COMPARÁVEIS
A5: Fonte | B5: Endereço / condomínio | C5: Tipo | D5: Área m² | E5: Quartos | F5: Vagas | G5: Preço | H5: Preço/m² | I5: Aluguel | J5: Condomínio | K5: Data | L5: Link | M5: Observações
A6: ZAP | B6: Residencial Piazza San Pietro | C6: Apartamento | D6: 47 | E6: 2 | F6: 1 | G6: 320000 | H6: 6808.5106 | I6: 1700 | J6: 510 | K6: 14/09/2026 | M6: Mesmo condomínio
A7: Chaves na Mão | B7: Residencial Piazza San Pietro | C7: Apartamento | D7: 47.76 | E7: 2 | F7: 1 | G7: 300000 | H7: 6281.407 | I7: 1700 | J7: 510 | K7: 14/09/2026 | M7: Referência de mercado
A8: Caixa | B8: Unidade em análise | C8: Apartamento | D8: 47.76 | E8: 3 | F8: 1 | G8: 191651.31 | H8: 4012.7996 | I8: 1900 | J8: 510 | K8: 14/09/2026 | M8: Preço do leilão
A28: 📊 CONCLUSÕES
A29: Campo | B29: Valor | C29: Tipo | D29: Observação | E29: Fonte
A30: Valor mercado conservador | B30: 270000 | C30: INPUT
A31: Valor mercado provável | B31: 290000 | C31: INPUT
A32: Score localização | B32: 85 | C32: INPUT
A33: Score liquidez | B33: 80 | C33: INPUT
A34: Preço/m² provável | B34: =IFERROR(B31/INDEX($D$6:$D$25,MATCH(MAX($G$6:$G$25),$G$6:$G$25,0)),0) -> 6170.2128 | C34: INPUT
A35: Aluguel provável | B35: 1900 | C35: INPUT
A36: Tempo provável de venda | B36: 60-90 dias | C36: INPUT
A37: Valorização esperada | B37: 0.05 | C37: INPUT

Sheet 06 - Contexto Humano
A1: 06 — CONTEXTO HUMANO
A2: 🔵 INPUT manual | 🟢 cálculo | Registre evidências e fontes
A4: 🧑 CONTEXTO E CONFORTO
A5: Critério | B5: Valor | C5: Tipo | D5: O que observar | E5: Fonte | F5: Data
A6: Perfil proprietário anterior | C6: INPUT
A7: Tempo de propriedade | C7: INPUT
A8: Tempo de residência | C8: INPUT
A9: Imóvel ocupado? | C9: INPUT
A10: Idade aproximada, se disponível | C10: INPUT
A11: Indícios de vulnerabilidade | C11: INPUT
A12: Situação aparente | C12: INPUT
A13: Histórico de inadimplência | C13: INPUT
A14: Observações humanas | C14: INPUT
A15: Conforto pessoal com aquisição | C15: INPUT
A18: Índice de Conforto Pessoal | B18: 85 | C18: INPUT | D18: 0 a 100
A20: Score Contexto Humano | B20: =B18 -> 85 | C20: CALCULADO

Sheet 07 - Histórico
A1: 07 — HISTÓRICO DA ANÁLISE
A2: 🔵 INPUT manual | 🟢 cálculo | Registre evidências e fontes
A4: Data | B4: Etapa | C4: Evento / alteração | D4: Lance | E4: Valor mercado | F4: Custo total | G4: ROI | H4: Score | I4: Decisão | J4: Responsável | K4: Fonte/evidência | L4: Observações

Sheet 08 - Documentos
A1: 08 — DOCUMENTOS E EVIDÊNCIAS
A2: 🔵 INPUT manual | 🟢 cálculo | Registre evidências e fontes
A4: Tipo | B4: Documento | C4: Data | D4: Fonte | E4: Link / localização | F4: Status | G4: O que comprova | H4: Observações

Sheet 09 - Leiloeiro & Pré-Lance
A1: MÉTODO JABES — LEILOEIRO & PRÉ-LANCE
A2: 🔵 INPUT manual | 🟢 validação | 🔴 bloqueio / reprovação | Tudo deve ter fonte/evidência
A4: 🔨 DADOS DO LEILOEIRO
A5: Campo | B5: Valor | C5: Status / Critério | D5: Fonte / Evidência
A6: Nome do leiloeiro | B6: Ives Harrisson Nasar dos Santos | C6: Conferir no edital vigente | D6: Edital 0031/0326-CPVE/RE
A7: Registro / matrícula JUC | B7: PREENCHER | C7: Obrigatório conferir | D7: Fonte oficial / edital / JUC
A8: CPF/CNPJ | B8: PREENCHER | C8: Conferir se disponível | D8: Fonte oficial
A9: Empresa / marca | B9: Nasar Leilões | C9: Conferir | D9: Edital vigente
A10: Site / plataforma | B10: PREENCHER | C10: Conferir domínio oficial | D10: Edital / site oficial
A11: E-mail oficial | B11: PREENCHER | C11: Não usar contato não confirmado | D11: Fonte oficial
A12: Telefone oficial | B12: PREENCHER | C12: Não usar contato não confirmado | D12: Fonte oficial
A13: Comissão | B13: 5% da proposta | C13: Confirmada no edital; fora do lance | D13: Edital 0031/0326-CPVE/RE
A14: Forma/prazo da comissão | B14: Paga pelo arrematante/classificado; no dia da sessão | C14: Conferir edital vigente | D14: Edital 0031/0326-CPVE/RE
A15: Dados bancários para pagamento | B15: PREENCHER APENAS APÓS HOMOLOGAÇÃO/ORIENTAÇÃO OFICIAL | C15: Nunca confiar em mensagem isolada | D15: Edital / canal oficial
A17: 📜 DADOS DO CERTAME
A18: Campo | B18: Valor | C18: Status / Critério | D18: Fonte / Evidência
A19: Edital | B19: 0031/0326-CPVE/RE | C19: Conferir versão vigente | D19: Edital vigente
A20: Item do imóvel | B20: 227 | C20: Deve bater com o imóvel | D20: Edital vigente
A21: Data/hora da sessão | B21: 15/09/2026 10:00 (PDF) — portal Caixa informa 29/09/2026 10:00 | C21: ⚠️ DIVERGÊNCIA — confirmar antes do lance | D21: Portal Caixa + edital
A22: Plataforma da sessão | B22: Nasar Leilões | C22: Conferir acesso no dia | D22: Edital vigente
A23: Valor mínimo | B23: R$ 191.651,31 | C23: Atualizar se houver nova publicação | D23: Portal Caixa / edital
A24: Comissão fora do lance | B24: 5% | C24: Somar no custo total | D24: Edital vigente
A25: Forma de pagamento | B25: Recursos próprios / FGTS conforme página; sem financiamento | C25: Conferir regra vigente | D25: Portal Caixa
A27: 🛑 HARD STOPS — NÃO DAR LANCE SE...
A28: Campo | B28: Valor | C28: Status / Critério | D28: Fonte / Evidência
A29: Edital vigente não confirmado | B29: NÃO | C29: REPROVAR se não houver versão válida
A30: Data/hora/plataforma divergente sem confirmação | B30: NÃO | C30: REPROVAR / PAUSAR
A31: Evicção não atendida pelo Método Jabes | B31: NÃO | C31: REPROVAR
A32: Matrícula / situação jurídica com dúvida material | B32: NÃO | C32: REPROVAR
A33: Débitos ou ocupação sem estimativa confiável | B33: NÃO | C33: REPROVAR / PAUSAR
A34: Custo total acima do orçamento definido | B34: NÃO | C34: REPROVAR
A35: Lance necessário acima do lance máximo | B35: NÃO | C35: NÃO ENTRAR
A36: Pagamento/comissão não compreendidos | B36: NÃO | C36: NÃO ENTRAR
A37: Necessidade de advogado para aceitar o risco | B37: NÃO | C37: REPROVAR pelo critério pessoal
A39: ✅ CHECKLIST PRÉ-LANCE — REVALIDAÇÃO
A40: Campo | B40: Valor | C40: Status / Critério | D40: Fonte / Evidência
A41: Edital vigente conferido | B41: NÃO | C41: Deve ser SIM
A42: Matrícula/documentação rechecadas | B42: NÃO | C42: Deve ser SIM
A43: Valor mínimo atualizado | B43: NÃO | C43: Deve ser SIM
A44: Comissão confirmada | B44: NÃO | C44: Deve ser SIM
...
